Workbook

Sheet Recap
C1: Year 1 | E1: Year 2
A2: Revenue
B3: ARR | D3: =sum('Financial Model'!C66:N66) -> 392518.56 | F3: =sum('Financial Model'!O66:Z66) -> 1952807.1 | H3: Note: To edit the numbers, first make a copy of this sheet (File > Make a copy).
A5: Costs | H5: Made by Gary Gaspar
B6: Costs of Good Sold | C6: =D6/$D$3 -> 0.075857704 | D6: =sum('Financial Model'!C71:N71) -> 29775.557 | E6: =F6/$F$3 -> 0.0392175 | F6: =sum('Financial Model'!O71:Z71) -> 76584.212 | H6: =HYPERLINK("https://marker.io?utm_source=spreadsheet&utm_medium=template&utm_campaign=saas-financial-model","https://marker.io") -> https://marker.io
B7: Sales & Marketing | C7: =D7/$D$3 -> 0.060571802 | D7: =sum('Financial Model'!C77:N77) -> 23775.557 | E7: =F7/$F$3 -> 0.036145 | F7: =sum('Financial Model'!O77:Z77) -> 70584.212
B8: Research & Development | C8: =D8/$D$3 -> 0.70315146 | D8: =sum('Financial Model'!C80:N80) -> 276000 | E8: =F8/$F$3 -> 0.20278501 | F8: =sum('Financial Model'!O80:Z80) -> 396000
B9: General & Administrative | C9: =D9/$D$3 -> 0.42393918 | D9: =sum('Financial Model'!C83:N83) -> 166404 | E9: =F9/$F$3 -> 0.085212719 | F9: =sum('Financial Model'!O83:Z83) -> 166404
A11: EBIT | D11: =D3-sum(D6:D9) -> -103436.55 | F11: =F3-sum(F6:F9) -> 1243234.6
A14: Cash needed to cover costs | F14: =sumif('Financial Model'!C87:Z87,"<0") -> -132357.34

Sheet Growth Hypotheses
B1: Year 1 | F1: Year 2
A2: Hypotheses | B2: Q1 | C2: Q2 | D2: Q3 | E2: Q4 | F2: Q1 | G2: Q2 | H2: Q3 | I2: Q4
A3: Average monthly price of subscriptions | B3: 2500 | C3: 2500 | D3: 2500 | E3: 2500 | F3: 2900 | G3: 2900 | H3: 2900 | I3: 2900
A4: Monthly growth rate in number of new customer | B4: 0.15 | C4: 0.12 | D4: 0.1 | E4: 0.08 | F4: 0.08 | G4: 0.07 | H4: 0.06 | I4: 0.05
A5: Monthly revenue churn rate | B5: 0.003 | C5: 0.003 | D5: 0.004 | E5: 0.004 | F5: 0.004 | G5: 0.004 | H5: 0.004 | I5: 0.004
A8: Number of new customers added last month | B8: 1 | C8: Cannot be ZERO
A9: Starting MRR | B9: 2500

Sheet Costs Hypotheses
A1: Personnel
C2: Name (optional) | D2: Yearly Cost (tax included) | E2: Starting month | F2: Category
B3: CEO | C3: David Youssef | D3: 120000 | E3: 1 | F3: =if(or(B3="CEO",B3="CTO"),"General & Administrative",if(B3="Engineer","Research & Development",if(or(B3="Customer Success",B3="Sales",B3="Marketing"),"Sales & Marketing",if(B3="Support","Support","N/A")))) -> General & Administrative
B4: Engineer | C4: Igor Malovitsa (CTO) | D4: 120000 | E4: 1 | F4: =if(or(B4="CEO",B4="CTO"),"General & Administrative",if(B4="Engineer","Research & Development",if(or(B4="Customer Success",B4="Sales",B4="Marketing"),"Sales & Marketing",if(B4="Support","Support","N/A")))) -> Research & Development
B5: Engineer | C5: Eng Hire #1 | D5: 120000 | E5: 4 | F5: =if(or(B5="CEO",B5="CTO"),"General & Administrative",if(B5="Engineer","Research & Development",if(or(B5="Customer Success",B5="Sales",B5="Marketing"),"Sales & Marketing",if(B5="Support","Support","N/A")))) -> Research & Development
B6: Engineer | C6: Eng Hire #2 | D6: 120000 | E6: 10 | F6: =if(or(B6="CEO",B6="CTO"),"General & Administrative",if(B6="Engineer","Research & Development",if(or(B6="Customer Success",B6="Sales",B6="Marketing"),"Sales & Marketing",if(B6="Support","Support","N/A")))) -> Research & Development
F7: =if(or(B7="CEO",B7="CTO"),"General & Administrative",if(B7="Engineer","Research & Development",if(or(B7="Customer Success",B7="Sales",B7="Marketing"),"Sales & Marketing",if(B7="Support","Support","N/A")))) -> N/A
F8: =if(or(B8="CEO",B8="CTO"),"General & Administrative",if(B8="Engineer","Research & Development",if(or(B8="Customer Success",B8="Sales",B8="Marketing"),"Sales & Marketing",if(B8="Support","Support","N/A")))) -> N/A
F9: =if(or(B9="CEO",B9="CTO"),"General & Administrative",if(B9="Engineer","Research & Development",if(or(B9="Customer Success",B9="Sales",B9="Marketing"),"Sales & Marketing",if(B9="Support","Support","N/A")))) -> N/A
F10: =if(or(B10="CEO",B10="CTO"),"General & Administrative",if(B10="Engineer","Research & Development",if(or(B10="Customer Success",B10="Sales",B10="Marketing"),"Sales & Marketing",if(B10="Support","Support","N/A")))) -> N/A
F11: =if(or(B11="CEO",B11="CTO"),"General & Administrative",if(B11="Engineer","Research & Development",if(or(B11="Customer Success",B11="Sales",B11="Marketing"),"Sales & Marketing",if(B11="Support","Support","N/A")))) -> N/A
F12: =if(or(B12="CEO",B12="CTO"),"General & Administrative",if(B12="Engineer","Research & Development",if(or(B12="Customer Success",B12="Sales",B12="Marketing"),"Sales & Marketing",if(B12="Support","Support","N/A")))) -> N/A
F13: =if(or(B13="CEO",B13="CTO"),"General & Administrative",if(B13="Engineer","Research & Development",if(or(B13="Customer Success",B13="Sales",B13="Marketing"),"Sales & Marketing",if(B13="Support","Support","N/A")))) -> N/A
F14: =if(or(B14="CEO",B14="CTO"),"General & Administrative",if(B14="Engineer","Research & Development",if(or(B14="Customer Success",B14="Sales",B14="Marketing"),"Sales & Marketing",if(B14="Support","Support","N/A")))) -> N/A
F15: =if(or(B15="CEO",B15="CTO"),"General & Administrative",if(B15="Engineer","Research & Development",if(or(B15="Customer Success",B15="Sales",B15="Marketing"),"Sales & Marketing",if(B15="Support","Support","N/A")))) -> N/A
F16: =if(or(B16="CEO",B16="CTO"),"General & Administrative",if(B16="Engineer","Research & Development",if(or(B16="Customer Success",B16="Sales",B16="Marketing"),"Sales & Marketing",if(B16="Support","Support","N/A")))) -> N/A
F17: =if(or(B17="CEO",B17="CTO"),"General & Administrative",if(B17="Engineer","Research & Development",if(or(B17="Customer Success",B17="Sales",B17="Marketing"),"Sales & Marketing",if(B17="Support","Support","N/A")))) -> N/A
F18: =if(or(B18="CEO",B18="CTO"),"General & Administrative",if(B18="Engineer","Research & Development",if(or(B18="Customer Success",B18="Sales",B18="Marketing"),"Sales & Marketing",if(B18="Support","Support","N/A")))) -> N/A
... F22: =if(or(B22="CEO",B22="CTO"),"General & Administrative",if(B22="Engineer","Research & Development",if(or(B22="Customer Success",B22="Sales",B22="Marketing"),"Sales & Marketing",if(B22="Support","Support","N/A")))) -> N/A
A24: Marketing spending
D25: % of MRR
B26: Adwords | D26: 0.02
B27: Social / display ads | D27: 0.01
A29: Cost of good sold
B30: Payement Processing fees | D30: 0.03
B31: Hosting & Bandwidth | D31: 1500
A33: Miscellaneous
B34: AI Agent APIs (3 x $1K/mo) | D34: 3000
B35: Software subscriptions (CRM, monitoring) | D35: 1000
B36: Legal, accountants, IP/patents | D36: 2000
B37: Travel / conferences | D37: 500
B38: Remote work (no office) | D38: 0
B39: Internet, supplies | D39: 200
B40: Insurance (D&O, E&O) | D40: 667
B41: Content / SEO / community | D41: 500
B42: Cognitive attestation license (future) | D42: 0

Sheet Financial Model
C1: Year 1 | O1: Year 2
A2: Month | C2: 42736 | D2: 42767 | E2: 42795 | F2: 42826 | G2: 42856 | H2: 42887 | I2: 42917 | J2: 42948 | K2: 42979 | L2: 43009 | M2: 43040 | N2: 43070 | O2: 43101 | P2: 43132 | Q2: 43160 | R2: 43191 | S2: 43221 | T2: 43252 | U2: 43282 | V2: 43313 | W2: 43344 | X2: 43374 | Y2: 43405 | Z2: 43435
A3: Month N | C3: 1 | D3: 2 | E3: 3 | F3: 4 | G3: 5 | H3: 6 | I3: 7 | J3: 8 | K3: 9 | L3: 10 | M3: 11 | N3: 12 | O3: 13 | P3: 14 | Q3: 15 | R3: 16 | S3: 17 | T3: 18 | U3: 19 | V3: 20 | W3: 21 | X3: 22 | Y3: 23 | Z3: 24
A4: REVENUE
A6: Revenue & customer Growth
B7: Average revenue per new customer | C7: ='Growth Hypotheses'!B3 -> 2500 | D7: ='Growth Hypotheses'!B3 -> 2500 | E7: ='Growth Hypotheses'!B3 -> 2500 | F7: ='Growth Hypotheses'!C3 -> 2500 | G7: ='Growth Hypotheses'!C3 -> 2500 | H7: ='Growth Hypotheses'!C3 -> 2500 | I7: ='Growth Hypotheses'!D3 -> 2500 | J7: ='Growth Hypotheses'!D3 -> 2500 | K7: ='Growth Hypotheses'!D3 -> 2500 | L7: ='Growth Hypotheses'!E3 -> 2500 | M7: ='Growth Hypotheses'!E3 -> 2500 | N7: ='Growth Hypotheses'!E3 -> 2500 | O7: ='Growth Hypotheses'!F3 -> 2900 | P7: ='Growth Hypotheses'!F3 -> 2900 | Q7: ='Growth Hypotheses'!F3 -> 2900 | R7: ='Growth Hypotheses'!G3 -> 2900 | S7: ='Growth Hypotheses'!G3 -> 2900 | T7: ='Growth Hypotheses'!G3 -> 2900 | U7: ='Growth Hypotheses'!H3 -> 2900 | V7: ='Growth Hypotheses'!H3 -> 2900 | W7: ='Growth Hypotheses'!H3 -> 2900 | X7: ='Growth Hypotheses'!I3 -> 2900 | Y7: ='Growth Hypotheses'!I3 -> 2900 | Z7: ='Growth Hypotheses'!I3 -> 2900
B8: New customers | C8: ='Growth Hypotheses'!B8+('Growth Hypotheses'!B8*'Growth Hypotheses'!B4) -> 1.15 | D8: =C8+(C8*'Growth Hypotheses'!B4) -> 1.3225 | E8: =D8+(D8*'Growth Hypotheses'!B4) -> 1.520875 | F8: =E8+(E8*'Growth Hypotheses'!C4) -> 1.70338 | G8: =F8+(F8*'Growth Hypotheses'!C4) -> 1.9077856 | H8: =G8+(G8*'Growth Hypotheses'!C4) -> 2.1367199 | I8: =H8+(H8*'Growth Hypotheses'!D4) -> 2.3503919 | J8: =I8+(I8*'Growth Hypotheses'!D4) -> 2.585431 | K8: =J8+(J8*'Growth Hypotheses'!D4) -> 2.8439742 | L8: =K8+(K8*'Growth Hypotheses'!E4) -> 3.0714921 | M8: =L8+(L8*'Growth Hypotheses'!E4) -> 3.3172114 | N8: =M8+(M8*'Growth Hypotheses'!E4) -> 3.5825884 | O8: =N8+(N8*'Growth Hypotheses'!F4) -> 3.8691954 | P8: =O8+(O8*'Growth Hypotheses'!F4) -> 4.1787311 | Q8: =P8+(P8*'Growth Hypotheses'!F4) -> 4.5130296 | R8: =Q8+(Q8*'Growth Hypotheses'!G4) -> 4.8289416 | S8: =R8+(R8*'Growth Hypotheses'!G4) -> 5.1669675 | T8: =S8+(S8*'Growth Hypotheses'!G4) -> 5.5286553 | U8: =T8+(T8*'Growth Hypotheses'!H4) -> 5.8603746 | V8: =U8+(U8*'Growth Hypotheses'!H4) -> 6.2119971 | W8: =V8+(V8*'Growth Hypotheses'!H4) -> 6.5847169 | X8: =W8+(W8*'Growth Hypotheses'!I4) -> 6.9139527 | Y8: =X8+(X8*'Growth Hypotheses'!I4) -> 7.2596504 | Z8: =Y8+(Y8*'Growth Hypotheses'!I4) -> 7.6226329
B9: Churn Rate | C9: ='Growth Hypotheses'!B5 -> 0.003 | D9: ='Growth Hypotheses'!B5 -> 0.003 | E9: ='Growth Hypotheses'!B5 -> 0.003 | F9: ='Growth Hypotheses'!C5 -> 0.003 | G9: ='Growth Hypotheses'!C5 -> 0.003 | H9: ='Growth Hypotheses'!C5 -> 0.003 | I9: ='Growth Hypotheses'!D5 -> 0.004 | J9: ='Growth Hypotheses'!D5 -> 0.004 | K9: ='Growth Hypotheses'!D5 -> 0.004 | L9: ='Growth Hypotheses'!E5 -> 0.004 | M9: ='Growth Hypotheses'!E5 -> 0.004 | N9: ='Growth Hypotheses'!E5 -> 0.004 | O9: ='Growth Hypotheses'!F5 -> 0.004 | P9: ='Growth Hypotheses'!F5 -> 0.004 | Q9: ='Growth Hypotheses'!F5 -> 0.004 | R9: ='Growth Hypotheses'!G5 -> 0.004 | S9: ='Growth Hypotheses'!G5 -> 0.004 | T9: ='Growth Hypotheses'!G5 -> 0.004 | U9: ='Growth Hypotheses'!H5 -> 0.004 | V9: ='Growth Hypotheses'!H5 -> 0.004 | W9: ='Growth Hypotheses'!H5 -> 0.004 | X9: ='Growth Hypotheses'!I5 -> 0.004 | Y9: ='Growth Hypotheses'!I5 -> 0.004 | Z9: ='Growth Hypotheses'!I5 -> 0.004
A10: Month Recurring Revenue
B11: New MRR | C11: =C8*C7 -> 2875 | D11: =D8*D7 -> 3306.25 | E11: =E8*E7 -> 3802.1875 | F11: =F8*F7 -> 4258.45 | G11: =G8*G7 -> 4769.464 | H11: =H8*H7 -> 5341.7997 | I11: =I8*I7 -> 5875.9796 | J11: =J8*J7 -> 6463.5776 | ... Z11: =Z8*Z7 -> 22105.635
B12: Lost MRR | C12: =C13*C9 -> 7.5 | D12: =D13*D9 -> 16.1025 | E12: =E13*E9 -> 25.972942 | F12: =F13*F9 -> 37.301586 | G12: =G13*G9 -> 49.965031 | H12: =H13*H9 -> 64.123528 | I12: =I13*I9 -> 106.60874 | J12: =J13*J9 -> 129.68623 | ... Z12: =Z13*Z9 -> 962.29092
B13: MRR from last month | C13: ='Growth Hypotheses'!B9 -> 2500 | D13: =C14 -> 5367.5 | E13: =D14 -> 8657.6475 | F13: =E14 -> 12433.862 | G13: =F14 -> 16655.01 | H13: =G14 -> 21374.509 | I13: =H14 -> 26652.186 | J13: =I14 -> 32421.556 | K13: =J14 -> 38755.448 | ... Z13: =Y14 -> 240572.73
B14: Gross MRR | C14: =C13+C11-C12 -> 5367.5 | D14: =D13+D11-D12 -> 8657.6475 | E14: =E13+E11-E12 -> 12433.862 | F14: =F13+F11-F12 -> 16655.01 | G14: =G13+G11-G12 -> 21374.509 | H14: =H13+H11-H12 -> 26652.186 | I14: =I13+I11-I12 -> 32421.556 | J14: =J13+J11-J12 -> 38755.448 | ... Z14: =Z13+Z11-Z12 -> 261716.07
B15: MRR Growth rate | D15: =(D14-C14)/C14 -> 0.61297578 | E15: =(E14-D14)/D14 -> 0.43617098 | F15: =(F14-E14)/E14 -> 0.33948812 | G15: =(G14-F14)/F14 -> 0.28336812 | H15: =(H14-G14)/G14 -> 0.24691449 | I15: =(I14-H14)/H14 -> 0.21646896 | J15: =(J14-I14)/I14 -> 0.1953605 | K15: =(K14-J14)/J14 -> 0.17945641 | ... Z15: =(Z14-Y14)/Y14 -> 0.087887536
B16: Payment Processing | C16: =C14*'Costs Hypotheses'!$D$30 -> 161.025 | D16: =D14*'Costs Hypotheses'!$D$30 -> 259.72942 | E16: =E14*'Costs Hypotheses'!$D$30 -> 373.01586 | F16: =F14*'Costs Hypotheses'!$D$30 -> 499.65031 | G16: =G14*'Costs Hypotheses'!$D$30 -> 641.23528 | H16: =H14*'Costs Hypotheses'!$D$30 -> 799.56557 | I16: =I14*'Costs Hypotheses'!$D$30 -> 972.64669 | J16: =J14*'Costs Hypotheses'!$D$30 -> 1162.6634 | ... Z16: =Z14*'Costs Hypotheses'!$D$30 -> 7851.4822
B17: Net MRR | C17: =C14-C16 -> 5206.475 | D17: =D14-D16 -> 8397.9181 | E17: =E14-E16 -> 12060.846 | F17: =F14-F16 -> 16155.36 | G17: =G14-G16 -> 20733.274 | H17: =H14-H16 -> 25852.62 | I17: =I14-I16 -> 31448.91 | J17: =J14-J16 -> 37592.784 | ... Z17: =Z14-Z16 -> 253864.59
A19: COSTS
A21: Personnel
B22: =+CONCATENATE('Costs Hypotheses'!B3," - ",'Costs Hypotheses'!C3) -> CEO - David Youssef | C22: =if('Costs Hypotheses'!$E3<=C$3,('Costs Hypotheses'!$D3/12),0) -> 10000 | D22: =if('Costs Hypotheses'!$E3<=D$3,('Costs Hypotheses'!$D3/12),0) -> 10000 | E22: =if('Costs Hypotheses'!$E3<=E$3,('Costs Hypotheses'!$D3/12),0) -> 10000 | F22: =if('Costs Hypotheses'!$E3<=F$3,('Costs Hypotheses'!$D3/12),0) -> 10000 | G22: =if('Costs Hypotheses'!$E3<=G$3,('Costs Hypotheses'!$D3/12),0) -> 10000 | H22: =if('Costs Hypotheses'!$E3<=H$3,('Costs Hypotheses'!$D3/12),0) -> 10000 | I22: =if('Costs Hypotheses'!$E3<=I$3,('Costs Hypotheses'!$D3/12),0) -> 10000 | J22: =if('Costs Hypotheses'!$E3<=J$3,('Costs Hypotheses'!$D3/12),0) -> 10000 | ... Z22: =if('Costs Hypotheses'!$E3<=Z$3,('Costs Hypotheses'!$D3/12),0) -> 10000
B23: =+CONCATENATE('Costs Hypotheses'!B4," - ",'Costs Hypotheses'!C4) -> Engineer - Igor Malovitsa (CTO) | C23: =if('Costs Hypotheses'!$E4<=C$3,('Costs Hypotheses'!$D4/12),0) -> 10000 | D23: =if('Costs Hypotheses'!$E4<=D$3,('Costs Hypotheses'!$D4/12),0) -> 10000 | E23: =if('Costs Hypotheses'!$E4<=E$3,('Costs Hypotheses'!$D4/12),0) -> 10000 | F23: =if('Costs Hypotheses'!$E4<=F$3,('Costs Hypotheses'!$D4/12),0) -> 10000 | G23: =if('Costs Hypotheses'!$E4<=G$3,('Costs Hypotheses'!$D4/12),0) -> 10000 | H23: =if('Costs Hypotheses'!$E4<=H$3,('Costs Hypotheses'!$D4/12),0) -> 10000 | I23: =if('Costs Hypotheses'!$E4<=I$3,('Costs Hypotheses'!$D4/12),0) -> 10000 | J23: =if('Costs Hypotheses'!$E4<=J$3,('Costs Hypotheses'!$D4/12),0) -> 10000 | ... Z23: =if('Costs Hypotheses'!$E4<=Z$3,('Costs Hypotheses'!$D4/12),0) -> 10000
B24: =+CONCATENATE('Costs Hypotheses'!B5," - ",'Costs Hypotheses'!C5) -> Engineer - Eng Hire #1 | C24: =if('Costs Hypotheses'!$E5<=C$3,('Costs Hypotheses'!$D5/12),0) -> 0 | D24: =if('Costs Hypotheses'!$E5<=D$3,('Costs Hypotheses'!$D5/12),0) -> 0 | E24: =if('Costs Hypotheses'!$E5<=E$3,('Costs Hypotheses'!$D5/12),0) -> 0 | F24: =if('Costs Hypotheses'!$E5<=F$3,('Costs Hypotheses'!$D5/12),0) -> 10000 | G24: =if('Costs Hypotheses'!$E5<=G$3,('Costs Hypotheses'!$D5/12),0) -> 10000 | H24: =if('Costs Hypotheses'!$E5<=H$3,('Costs Hypotheses'!$D5/12),0) -> 10000 | I24: =if('Costs Hypotheses'!$E5<=I$3,('Costs Hypotheses'!$D5/12),0) -> 10000 | J24: =if('Costs Hypotheses'!$E5<=J$3,('Costs Hypotheses'!$D5/12),0) -> 10000 | ... Z24: =if('Costs Hypotheses'!$E5<=Z$3,('Costs Hypotheses'!$D5/12),0) -> 10000
B25: =+CONCATENATE('Costs Hypotheses'!B6," - ",'Costs Hypotheses'!C6) -> Engineer - Eng Hire #2 | C25: =if('Costs Hypotheses'!$E6<=C$3,('Costs Hypotheses'!$D6/12),0) -> 0 | D25: =if('Costs Hypotheses'!$E6<=D$3,('Costs Hypotheses'!$D6/12),0) -> 0 | E25: =if('Costs Hypotheses'!$E6<=E$3,('Costs Hypotheses'!$D6/12),0) -> 0 | F25: =if('Costs Hypotheses'!$E6<=F$3,('Costs Hypotheses'!$D6/12),0) -> 0 | G25: =if('Costs Hypotheses'!$E6<=G$3,('Costs Hypotheses'!$D6/12),0) -> 0 | H25: =if('Costs Hypotheses'!$E6<=H$3,('Costs Hypotheses'!$D6/12),0) -> 0 | I25: =if('Costs Hypotheses'!$E6<=I$3,('Costs Hypotheses'!$D6/12),0) -> 0 | J25: =if('Costs Hypotheses'!$E6<=J$3,('Costs Hypotheses'!$D6/12),0) -> 0 | ... Z25: =if('Costs Hypotheses'!$E6<=Z$3,('Costs Hypotheses'!$D6/12),0) -> 10000
B26: =+CONCATENATE('Costs Hypotheses'!B7," - ",'Costs Hypotheses'!C7) -> - | C26: =if('Costs Hypotheses'!$E7<=C$3,('Costs Hypotheses'!$D7/12),0) -> 0 | D26: =if('Costs Hypotheses'!$E7<=D$3,('Costs Hypotheses'!$D7/12),0) -> 0 | E26: =if('Costs Hypotheses'!$E7<=E$3,('Costs Hypotheses'!$D7/12),0) -> 0 | F26: =if('Costs Hypotheses'!$E7<=F$3,('Costs Hypotheses'!$D7/12),0) -> 0 | G26: =if('Costs Hypotheses'!$E7<=G$3,('Costs Hypotheses'!$D7/12),0) -> 0 | H26: =if('Costs Hypotheses'!$E7<=H$3,('Costs Hypotheses'!$D7/12),0) -> 0 | I26: =if('Costs Hypotheses'!$E7<=I$3,('Costs Hypotheses'!$D7/12),0) -> 0 | J26: =if('Costs Hypotheses'!$E7<=J$3,('Costs Hypotheses'!$D7/12),0) -> 0 | ... Z26: =if('Costs Hypotheses'!$E7<=Z$3,('Costs Hypotheses'!$D7/12),0) -> 0
B27: =+CONCATENATE('Costs Hypotheses'!B8," - ",'Costs Hypotheses'!C8) -> - | C27: =if('Costs Hypotheses'!$E8<=C$3,('Costs Hypotheses'!$D8/12),0) -> 0 | D27: =if('Costs Hypotheses'!$E8<=D$3,('Costs Hypotheses'!$D8/12),0) -> 0 | E27: =if('Costs Hypotheses'!$E8<=E$3,('Costs Hypotheses'!$D8/12),0) -> 0 | F27: =if('Costs Hypotheses'!$E8<=F$3,('Costs Hypotheses'!$D8/12),0) -> 0 | G27: =if('Costs Hypotheses'!$E8<=G$3,('Costs Hypotheses'!$D8/12),0) -> 0 | H27: =if('Costs Hypotheses'!$E8<=H$3,('Costs Hypotheses'!$D8/12),0) -> 0 | I27: =if('Costs Hypotheses'!$E8<=I$3,('Costs Hypotheses'!$D8/12),0) -> 0 | J27: =if('Costs Hypotheses'!$E8<=J$3,('Costs Hypotheses'!$D8/12),0) -> 0 | ... Z27: =if('Costs Hypotheses'!$E8<=Z$3,('Costs Hypotheses'!$D8/12),0) -> 0
B28: =+CONCATENATE('Costs Hypotheses'!B9," - ",'Costs Hypotheses'!C9) -> - | C28: =if('Costs Hypotheses'!$E9<=C$3,('Costs Hypotheses'!$D9/12),0) -> 0 | D28: =if('Costs Hypotheses'!$E9<=D$3,('Costs Hypotheses'!$D9/12),0) -> 0 | E28: =if('Costs Hypotheses'!$E9<=E$3,('Costs Hypotheses'!$D9/12),0) -> 0 | F28: =if('Costs Hypotheses'!$E9<=F$3,('Costs Hypotheses'!$D9/12),0) -> 0 | G28: =if('Costs Hypotheses'!$E9<=G$3,('Costs Hypotheses'!$D9/12),0) -> 0 | H28: =if('Costs Hypotheses'!$E9<=H$3,('Costs Hypotheses'!$D9/12),0) -> 0 | I28: =if('Costs Hypotheses'!$E9<=I$3,('Costs Hypotheses'!$D9/12),0) -> 0 | J28: =if('Costs Hypotheses'!$E9<=J$3,('Costs Hypotheses'!$D9/12),0) -> 0 | ... Z28: =if('Costs Hypotheses'!$E9<=Z$3,('Costs Hypotheses'!$D9/12),0) -> 0
B29: =+CONCATENATE('Costs Hypotheses'!B10," - ",'Costs Hypotheses'!C10) -> - | C29: =if('Costs Hypotheses'!$E10<=C$3,('Costs Hypotheses'!$D10/12),0) -> 0 | D29: =if('Costs Hypotheses'!$E10<=D$3,('Costs Hypotheses'!$D10/12),0) -> 0 | E29: =if('Costs Hypotheses'!$E10<=E$3,('Costs Hypotheses'!$D10/12),0) -> 0 | F29: =if('Costs Hypotheses'!$E10<=F$3,('Costs Hypotheses'!$D10/12),0) -> 0 | G29: =if('Costs Hypotheses'!$E10<=G$3,('Costs Hypotheses'!$D10/12),0) -> 0 | H29: =if('Costs Hypotheses'!$E10<=H$3,('Costs Hypotheses'!$D10/12),0) -> 0 | I29: =if('Costs Hypotheses'!$E10<=I$3,('Costs Hypotheses'!$D10/12),0) -> 0 | J29: =if('Costs Hypotheses'!$E10<=J$3,('Costs Hypotheses'!$D10/12),0) -> 0 | ... Z29: =if('Costs Hypotheses'!$E10<=Z$3,('Costs Hypotheses'!$D10/12),0) -> 0
B30: =+CONCATENATE('Costs Hypotheses'!B11," - ",'Costs Hypotheses'!C11) -> - | C30: =if('Costs Hypotheses'!$E11<=C$3,('Costs Hypotheses'!$D11/12),0) -> 0 | D30: =if('Costs Hypotheses'!$E11<=D$3,('Costs Hypotheses'!$D11/12),0) -> 0 | E30: =if('Costs Hypotheses'!$E11<=E$3,('Costs Hypotheses'!$D11/12),0) -> 0 | F30: =if('Costs Hypotheses'!$E11<=F$3,('Costs Hypotheses'!$D11/12),0) -> 0 | G30: =if('Costs Hypotheses'!$E11<=G$3,('Costs Hypotheses'!$D11/12),0) -> 0 | H30: =if('Costs Hypotheses'!$E11<=H$3,('Costs Hypotheses'!$D11/12),0) -> 0 | I30: =if('Costs Hypotheses'!$E11<=I$3,('Costs Hypotheses'!$D11/12),0) -> 0 | J30: =if('Costs Hypotheses'!$E11<=J$3,('Costs Hypotheses'!$D11/12),0) -> 0 | ... Z30: =if('Costs Hypotheses'!$E11<=Z$3,('Costs Hypotheses'!$D11/12),0) -> 0
B31: =+CONCATENATE('Costs Hypotheses'!B12," - ",'Costs Hypotheses'!C12) -> - | C31: =if('Costs Hypotheses'!$E12<=C$3,('Costs Hypotheses'!$D12/12),0) -> 0 | D31: =if('Costs Hypotheses'!$E12<=D$3,('Costs Hypotheses'!$D12/12),0) -> 0 | E31: =if('Costs Hypotheses'!$E12<=E$3,('Costs Hypotheses'!$D12/12),0) -> 0 | F31: =if('Costs Hypotheses'!$E12<=F$3,('Costs Hypotheses'!$D12/12),0) -> 0 | G31: =if('Costs Hypotheses'!$E12<=G$3,('Costs Hypotheses'!$D12/12),0) -> 0 | H31: =if('Costs Hypotheses'!$E12<=H$3,('Costs Hypotheses'!$D12/12),0) -> 0 | I31: =if('Costs Hypotheses'!$E12<=I$3,('Costs Hypotheses'!$D12/12),0) -> 0 | J31: =if('Costs Hypotheses'!$E12<=J$3,('Costs Hypotheses'!$D12/12),0) -> 0 | ... Z31: =if('Costs Hypotheses'!$E12<=Z$3,('Costs Hypotheses'!$D12/12),0) -> 0
B32: =+CONCATENATE('Costs Hypotheses'!B13," - ",'Costs Hypotheses'!C13) -> - | C32: =if('Costs Hypotheses'!$E13<=C$3,('Costs Hypotheses'!$D13/12),0) -> 0 | D32: =if('Costs Hypotheses'!$E13<=D$3,('Costs Hypotheses'!$D13/12),0) -> 0 | E32: =if('Costs Hypotheses'!$E13<=E$3,('Costs Hypotheses'!$D13/12),0) -> 0 | F32: =if('Costs Hypotheses'!$E13<=F$3,('Costs Hypotheses'!$D13/12),0) -> 0 | G32: =if('Costs Hypotheses'!$E13<=G$3,('Costs Hypotheses'!$D13/12),0) -> 0 | H32: =if('Costs Hypotheses'!$E13<=H$3,('Costs Hypotheses'!$D13/12),0) -> 0 | I32: =if('Costs Hypotheses'!$E13<=I$3,('Costs Hypotheses'!$D13/12),0) -> 0 | J32: =if('Costs Hypotheses'!$E13<=J$3,('Costs Hypotheses'!$D13/12),0) -> 0 | ... Z32: =if('Costs Hypotheses'!$E13<=Z$3,('Costs Hypotheses'!$D13/12),0) -> 0
B33: =+CONCATENATE('Costs Hypotheses'!B14," - ",'Costs Hypotheses'!C14) -> - | C33: =if('Costs Hypotheses'!$E14<=C$3,('Costs Hypotheses'!$D14/12),0) -> 0 | D33: =if('Costs Hypotheses'!$E14<=D$3,('Costs Hypotheses'!$D14/12),0) -> 0 | E33: =if('Costs Hypotheses'!$E14<=E$3,('Costs Hypotheses'!$D14/12),0) -> 0 | F33: =if('Costs Hypotheses'!$E14<=F$3,('Costs Hypotheses'!$D14/12),0) -> 0 | G33: =if('Costs Hypotheses'!$E14<=G$3,('Costs Hypotheses'!$D14/12),0) -> 0 | H33: =if('Costs Hypotheses'!$E14<=H$3,('Costs Hypotheses'!$D14/12),0) -> 0 | I33: =if('Costs Hypotheses'!$E14<=I$3,('Costs Hypotheses'!$D14/12),0) -> 0 | J33: =if('Costs Hypotheses'!$E14<=J$3,('Costs Hypotheses'!$D14/12),0) -> 0 | ... Z33: =if('Costs Hypotheses'!$E14<=Z$3,('Costs Hypotheses'!$D14/12),0) -> 0
... B41: =+CONCATENATE('Costs Hypotheses'!B22," - ",'Costs Hypotheses'!C22) -> - | C41: =if('Costs Hypotheses'!$E22<=C$3,('Costs Hypotheses'!$D22/12),0) -> 0 | D41: =if('Costs Hypotheses'!$E22<=D$3,('Costs Hypotheses'!$D22/12),0) -> 0 | E41: =if('Costs Hypotheses'!$E22<=E$3,('Costs Hypotheses'!$D22/12),0) -> 0 | F41: =if('Costs Hypotheses'!$E22<=F$3,('Costs Hypotheses'!$D22/12),0) -> 0 | G41: =if('Costs Hypotheses'!$E22<=G$3,('Costs Hypotheses'!$D22/12),0) -> 0 | H41: =if('Costs Hypotheses'!$E22<=H$3,('Costs Hypotheses'!$D22/12),0) -> 0 | I41: =if('Costs Hypotheses'!$E22<=I$3,('Costs Hypotheses'!$D22/12),0) -> 0 | J41: =if('Costs Hypotheses'!$E22<=J$3,('Costs Hypotheses'!$D22/12),0) -> 0 | ... Z41: =if('Costs Hypotheses'!$E22<=Z$3,('Costs Hypotheses'!$D22/12),0) -> 0
B42: Total Payroll | C42: =sum(C22:C41) -> 20000 | D42: =sum(D22:D41) -> 20000 | E42: =sum(E22:E41) -> 20000 | F42: =sum(F22:F41) -> 30000 | G42: =sum(G22:G41) -> 30000 | H42: =sum(H22:H41) -> 30000 | I42: =sum(I22:I41) -> 30000 | J42: =sum(J22:J41) -> 30000 | ... Z42: =sum(Z22:Z41) -> 40000
A44: Marketing Spending
B45: ='Costs Hypotheses'!B26 -> Adwords | C45: ='Costs Hypotheses'!$D26*C14 -> 107.35 | D45: ='Costs Hypotheses'!$D26*D14 -> 173.15295 | E45: ='Costs Hypotheses'!$D26*E14 -> 248.67724 | F45: ='Costs Hypotheses'!$D26*F14 -> 333.10021 | G45: ='Costs Hypotheses'!$D26*G14 -> 427.49019 | H45: ='Costs Hypotheses'!$D26*H14 -> 533.04371 | I45: ='Costs Hypotheses'!$D26*I14 -> 648.43113 | J45: ='Costs Hypotheses'!$D26*J14 -> 775.10896 | ... Z45: ='Costs Hypotheses'!$D26*Z14 -> 5234.3215
B46: ='Costs Hypotheses'!B27 -> Social / display ads | C46: ='Costs Hypotheses'!$D27*C14 -> 53.675 | D46: ='Costs Hypotheses'!$D27*D14 -> 86.576475 | E46: ='Costs Hypotheses'!$D27*E14 -> 124.33862 | F46: ='Costs Hypotheses'!$D27*F14 -> 166.5501 | G46: ='Costs Hypotheses'!$D27*G14 -> 213.74509 | H46: ='Costs Hypotheses'!$D27*H14 -> 266.52186 | I46: ='Costs Hypotheses'!$D27*I14 -> 324.21557 | J46: ='Costs Hypotheses'!$D27*J14 -> 387.55448 | ... Z46: ='Costs Hypotheses'!$D27*Z14 -> 2617.1607
B47: Total Marketing Spending | C47: =sum(C45:C46) -> 161.025 | D47: =sum(D45:D46) -> 259.72942 | E47: =sum(E45:E46) -> 373.01586 | F47: =sum(F45:F46) -> 499.65031 | G47: =sum(G45:G46) -> 641.23528 | H47: =sum(H45:H46) -> 799.56557 | I47: =sum(I45:I46) -> 972.64669 | J47: =sum(J45:J46) -> 1162.6634 | ... Z47: =sum(Z45:Z46) -> 7851.4822
A48: Hosting
B49: ='Costs Hypotheses'!B31 -> Hosting & Bandwidth | C49: ='Costs Hypotheses'!$D31 -> 1500 | D49: ='Costs Hypotheses'!$D31 -> 1500 | E49: ='Costs Hypotheses'!$D31 -> 1500 | F49: ='Costs Hypotheses'!$D31 -> 1500 | G49: ='Costs Hypotheses'!$D31 -> 1500 | H49: ='Costs Hypotheses'!$D31 -> 1500 | I49: ='Costs Hypotheses'!$D31 -> 1500 | J49: ='Costs Hypotheses'!$D31 -> 1500 | ... Z49: ='Costs Hypotheses'!$D31 -> 1500
B50: Total Hosting | C50: =C49 -> 1500 | D50: =D49 -> 1500 | E50: =E49 -> 1500 | F50: =F49 -> 1500 | G50: =G49 -> 1500 | H50: =H49 -> 1500 | I50: =I49 -> 1500 | J50: =J49 -> 1500 | ... Z50: =Z49 -> 1500
A51: ='Costs Hypotheses'!A33 -> Miscellaneous
...
